Workbook

Sheet Packages
A1: Digital invitation packages: price & cost per event (Philippines)
A2: Prices in blue are yours to set. Costs pull from Inputs and Monthly Costs.
B4: Basic | C4: Classic | D4: Signature | E4: Note
A5: Best for | B5: Simple parties, kids' birthdays | C5: Debuts, 18ths, sweet 16s (most popular) | D5: Weddings, big debuts
A6: Package price (₱) | B6: 1999 | C6: 3499 | D6: 5499 | E6: Positioned against PH market (₱800–₱5,997, see Market tab); more features than most at each tier.
A7: Includes custom domain (1 = yes) | B7: 0 | C7: 0 | D7: 1
A9: Your time per event (hours)
A10: Setup & configuration | B10: 0.5 | C10: 1 | D10: 1 | E10: Assumption: the template + new_event.py script does most setup; adjust after your first few clients.
A11: Design & customisation | B11: 1 | C11: 3 | D11: 4.5
A12: Revisions | B12: 0.5 | C12: 1.5 | D12: 2.5
A13: Client chat & guest support | B13: 0.5 | C13: 1 | D13: 1.5
A14: Testing & launch | B14: 0.5 | C14: 0.5 | D14: 0.5
A15: Total hours | B15: =SUM(B10:B14) -> 3 | C15: =SUM(C10:C14) -> 7 | D15: =SUM(D10:D14) -> 10
A17: Cost per event (₱)
A18: Your labour | B18: =B15*Inputs!$B$5 -> 750 | C18: =C15*Inputs!$B$5 -> 1750 | D18: =D15*Inputs!$B$5 -> 2500 | E18: Hours × your labour rate
A19: Platform & tools share | B19: ='Monthly Costs'!$B$13 -> 343.125 | C19: ='Monthly Costs'!$B$13 -> 343.125 | D19: ='Monthly Costs'!$B$13 -> 343.125 | E19: Vercel + Supabase + tools ÷ events per month
A20: Ads share | B20: ='Monthly Costs'!$B$14 -> 300 | C20: ='Monthly Costs'!$B$14 -> 300 | D20: ='Monthly Costs'!$B$14 -> 300 | E20: Monthly ads ÷ events per month
A21: Custom domain | B21: =B7*Inputs!$B$9*Inputs!$B$4 -> 0 | C21: =C7*Inputs!$B$9*Inputs!$B$4 -> 0 | D21: =D7*Inputs!$B$9*Inputs!$B$4 -> 732 | E21: Signature only (1 year)
A22: Payment fee | B22: =B6*Inputs!$B$12 -> 39.98 | C22: =C6*Inputs!$B$12 -> 69.98 | D22: =D6*Inputs!$B$12 -> 109.98 | E22: Price × payment fee %
A23: Income tax | B23: =B6*Inputs!$B$13 -> 159.92 | C23: =C6*Inputs!$B$13 -> 279.92 | D23: =D6*Inputs!$B$13 -> 439.92 | E23: Price × 8% (conservative)
A24: Total cost per event | B24: =SUM(B18:B23) -> 1593.025 | C24: =SUM(C18:C23) -> 2743.025 | D24: =SUM(D18:D23) -> 4425.025
A26: Profit (₱)
A27: Business profit (after paying yourself) | B27: =B6-B24 -> 405.975 | C27: =C6-C24 -> 755.975 | D27: =D6-D24 -> 1073.975 | E27: What the business keeps after your hourly pay
A28: Net margin | B28: =IFERROR(B27/B6,0) -> 0.20308904 | C28: =IFERROR(C27/C6,0) -> 0.21605459 | D28: =IFERROR(D27/D6,0) -> 0.19530369
A29: Your take-home (profit + labour) | B29: =B27+B18 -> 1155.975 | C29: =C27+C18 -> 2505.975 | D29: =D27+D18 -> 3573.975 | E29: If you do the work yourself, this is what you pocket
A30: Effective earnings per hour | B30: =IFERROR(B29/B15,0) -> 385.325 | C30: =IFERROR(C29/C15,0) -> 357.99643 | D30: =IFERROR(D29/D15,0) -> 357.3975 | E30: Take-home ÷ hours
A31: Cash cost (excluding your time) | B31: =B24-B18 -> 843.025 | C31: =C24-C18 -> 993.025 | D31: =D24-D18 -> 1925.025 | E31: Money that actually leaves your pocket
A33: What's included
A34: Envelope that opens to the invitation card | B34: ✓ | C34: ✓ | D34: ✓
A35: Live countdown + add-to-calendar (Google, Apple, Outlook) | B35: ✓ | C35: ✓ | D35: ✓
A36: Map & one-tap directions | B36: ✓ | C36: ✓ | D36: ✓
A37: Online RSVP (names, emails, wishes) | B37: ✓ | C37: ✓ | D37: ✓
A38: Private guest list for hosts (see who's coming) | B38: ✓ | C38: ✓ | D38: ✓
A39: Email confirmations with calendar invite | B39: — | C39: ✓ | D39: ✓
A40: Guest photo wall + all-photos page | B40: — | C40: ✓ | D40: ✓
A41: Theme: colours, fonts, wording | B41: Preset | C41: Custom | D41: Custom
A42: Decorations / motifs redrawn for your theme | B42: — | C42: — | D42: ✓
A43: Invitation card design | B43: Your own card | C43: Your own card | D43: Designed for you
A44: Web address | B44: yourname.vercel.app | C44: yourname.vercel.app | D44: Custom .com (1 yr)
A45: Revision rounds | B45: 1 | C45: 2 | D45: 3
...

Sheet Inputs
A1: Inputs & assumptions (edit the blue cells)
A2: Blue = your inputs, yellow = the ones worth reviewing first. Everything else in the workbook recalculates from here.
A3: Assumption | B3: Value | C3: Unit | D3: Source / note
A4: Exchange rate | B4: 61 | C4: ₱ per US$ | D4: Rate on 3 Aug 2026 was ₱60.92 (valutafx.com). Update to today's rate.
A5: Your labour rate | B5: 250 | C5: ₱ per hour | D5: Assumption: entry-level PH freelance web rate. Raise as you get faster/busier.
A6: Vercel Pro | B6: 20 | C6: US$ per month | D6: Hosting for all sites + email function. Hobby (free) plan does not allow commercial use, so Pro is required (vercel.com pricing; makerkit.dev/blog/saas/vercel-cost).
A7: Supabase Pro | B7: 25 | C7: US$ per month | D7: Database + photo storage. Free tier: 2 projects, 1 GB storage, pauses after 1 week idle (makerkit.dev/blog/md/saas/supabase-pricing).
A8: Use Supabase Pro? (1 = yes, 0 = free tier) | B8: 1 | C8: switch | D8: Start on the free tier (0) for your first few clients; switch to Pro (1) once photos pass ~1 GB or a site risks pausing. Assumes all events share one project (each event gets its own table and photo folder; the SQL files need the table name changed per event).
A9: Custom .com domain | B9: 12 | C9: US$ per year | D9: Assumption: typical .com registration (Namecheap/Porkbun range). Only charged on Signature or as an add-on.
A10: Design tools (e.g. Canva Pro) | B10: 0 | C10: ₱ per month | D10: Optional. Set your actual subscription if you use one.
A11: Instagram / Facebook ads | B11: 2400 | C11: ₱ per month | D11: Assumption: ₱80/day boosted story or reel. Set 0 if you only post organically.
A12: Payment fee | B12: 0.02 | C12: % of price | D12: Assumption for GCash/Maya business QR or card. Use 0% for personal GCash/bank transfer.
A13: Income tax (8% option) | B13: 0.08 | C13: % of price | D13: BIR 8% optional rate on gross sales for self-employed (first ₱250,000/yr is exempt, so this is conservative). Confirm with BIR/an accountant; register your business first.
A14: Gmail for confirmation emails | B14: 0 | C14: ₱ per month | D14: Free Gmail app password; ~500 emails/day limit is plenty per event.
A16: Expected events per month (package mix) | B16: Events | D16: Note
A17: Basic | B17: 3 | D17: Assumption: a realistic early month. Change it to see profit at your real volume.
A18: Classic | B18: 4
A19: Signature | B19: 1
A20: Total events per month | B20: =SUM(B17:B19) -> 8

Sheet Monthly Costs
A1: Monthly running costs (₱)
A3: Cost | B3: ₱ / month | C3: How it's calculated
A4: Vercel Pro | B4: =Inputs!B6*Inputs!B4 -> 1220 | C4: US$ price × exchange rate
A5: Supabase Pro | B5: =Inputs!B7*Inputs!B4*Inputs!B8 -> 1525 | C5: US$ price × exchange rate × Pro switch
A6: Gmail | B6: =Inputs!B14 -> 0 | C6: Free
A7: Design tools | B7: =Inputs!B10 -> 0 | C7: From Inputs
A8: Platform & tools subtotal | B8: =SUM(B4:B7) -> 2745
A9: Instagram / Facebook ads | B9: =Inputs!B11 -> 2400
A10: Total monthly overhead | B10: =B8+B9 -> 5145
A12: Events per month | B12: =Inputs!B20 -> 8
A13: Platform & tools per event | B13: =IFERROR(B8/B12,0) -> 343.125 | C13: Overhead spread across the month's events
A14: Ads per event | B14: =IFERROR(B9/B12,0) -> 300

Sheet Add-ons
A1: Add-ons (₱)
A3: Add-on | B3: Price | C3: Your cost | D3: Profit | E3: Cost basis
A4: Rush delivery (48 hours) | B4: 800 | C4: =1*Inputs!$B$5 -> 250 | D4: =B4-C4 -> 550 | E4: ~1 hour of overtime/reshuffling; you are mostly charging for priority
A5: Extra revision round | B5: 400 | C5: =1*Inputs!$B$5 -> 250 | D5: =B5-C5 -> 150 | E5: 1 hour
A6: Custom .com domain (1 year) | B6: 1000 | C6: =Inputs!$B$9*Inputs!$B$4 -> 732 | D6: =B6-C6 -> 268 | E6: Domain registration
A7: Invitation card design (if you don't have one) | B7: 1200 | C7: =3*Inputs!$B$5 -> 750 | D7: =B7-C7 -> 450 | E7: 3 hours
A8: Photo wall (Basic package) | B8: 700 | C8: =1*Inputs!$B$5 -> 250 | D8: =B8-C8 -> 450 | E8: 1 hour setup
A9: Email confirmations (Basic package) | B9: 500 | C9: =1*Inputs!$B$5 -> 250 | D9: =B9-C9 -> 250 | E9: 1 hour setup
A10: Keep site online +6 months | B10: 500 | C10: =0.5*Inputs!$B$5 -> 125 | D10: =B10-C10 -> 375 | E10: 30 min upkeep; hosting already covered
A11: Download all guest photos (ZIP) | B11: 300 | C11: =0.5*Inputs!$B$5 -> 125 | D11: =B11-C11 -> 175 | E11: 30 min
A12: QR code for printed invites | B12: 150 | C12: =0.25*Inputs!$B$5 -> 62.5 | D12: =B12-C12 -> 87.5 | E12: 15 min
A13: Instagram story teaser video of their invite | B13: 800 | C13: =2*Inputs!$B$5 -> 500 | D13: =B13-C13 -> 300 | E13: 2 hours (reuse the promo video template)
A15: Prices are suggestions (assumptions); hours are valued at your labour rate on Inputs.

Sheet Break-even
A1: Break-even & monthly projection
A3: Monthly overhead (platform + ads) | B3: ='Monthly Costs'!B10 -> 5145
A5: Per event | B5: Basic | C5: Classic | D5: Signature | E5: Total / mix
A6: Price | B6: =Packages!B6 -> 1999 | C6: =Packages!C6 -> 3499 | D6: =Packages!D6 -> 5499
A7: Variable cost (labour, domain, fees, tax) | B7: =Packages!B18+Packages!B21+Packages!B22+Packages!B23 -> 949.9 | C7: =Packages!C18+Packages!C21+Packages!C22+Packages!C23 -> 2099.9 | D7: =Packages!D18+Packages!D21+Packages!D22+Packages!D23 -> 3781.9
A8: Contribution to overhead | B8: =B6-B7 -> 1049.1 | C8: =C6-C7 -> 1399.1 | D8: =D6-D7 -> 1717.1
A9: Events needed to cover overhead (one package only) | B9: =IFERROR(ROUNDUP($B$3/B8,0),0) -> 5 | C9: =IFERROR(ROUNDUP($B$3/C8,0),0) -> 4 | D9: =IFERROR(ROUNDUP($B$3/D8,0),0) -> 3
A11: This month (from Inputs mix) | B11: Basic | C11: Classic | D11: Signature | E11: Total
A12: Events | B12: =Inputs!B17 -> 3 | C12: =Inputs!B18 -> 4 | D12: =Inputs!B19 -> 1 | E12: =SUM(B12:D12) -> 8
A13: Revenue | B13: =B6*B12 -> 5997 | C13: =C6*C12 -> 13996 | D13: =D6*D12 -> 5499 | E13: =SUM(B13:D13) -> 25492
A14: Variable costs | B14: =B7*B12 -> 2849.7 | C14: =C7*C12 -> 8399.6 | D14: =D7*D12 -> 3781.9 | E14: =SUM(B14:D14) -> 15031.2
A15: Contribution | B15: =B13-B14 -> 3147.3 | C15: =C13-C14 -> 5596.4 | D15: =D13-D14 -> 1717.1 | E15: =SUM(B15:D15) -> 10460.8
A16: Less: monthly overhead | E16: =-B3 -> -5145
A17: Business profit this month | E17: =E15+E16 -> 5315.8
A18: Plus your labour pay | E18: =SUMPRODUCT(Packages!B18:D18,B12:D12) -> 11750
A19: Your total take-home this month | E19: =E17+E18 -> 17065.8
A20: Total hours worked | E20: =SUMPRODUCT(Packages!B15:D15,B12:D12) -> 47

Sheet Market
A1: Philippine market check (Oct 2026)
A3: Provider | B3: Package | C3: Price | D3: What's mentioned | E3: Source
A4: E-Invitation (Logica Technology) | B4: Standard | C4: ₱800 | D4: RSVP, mobile sharing, fast delivery | E4: https://e-invitation.online/
A5: Click-Invitation | B5: Starter Package 1 | C5: ₱1,998 | D5: Wedding digital invitation with RSVP | E5: https://click-invitation.com/blog/affordable-wedding-digital-invitations-in-the-philippines-starter-package-1-for-only-php1-998
A6: Click-Invitation | B6: Starter Package 2 | C6: ₱2,998 | D6: RSVP tracking, online guest management | E6: https://click-invitation.com/blog/starter-package-2-the-complete-wedding-digital-invitation-experience-for-only-php2-998
A7: Specially Invited | B7: Essential | C7: from ₱2,497 | D7: Sub-domain website invitation, live RSVP, 2–5 days | E7: https://www.speciallyinvited.com/
A8: Specially Invited | B8: Signature | C8: ₱3,997 | D8: Personalised domain option | E8: https://www.speciallyinvited.com/
A9: Specially Invited | B9: Ultimate | C9: ₱5,997 | D9: Bespoke, domain-ready | E9: https://www.speciallyinvited.com/
A10: Etsy templates | B10: DIY template | C10: ≈US$3–33 | D10: Template only; you edit and host yourself | E10: https://www.etsy.com/market/filipino_digital_invitation
A12: Prices as listed in web search results in Oct 2026; check the sites for current offers. Our photo wall, email confirmations and host guest list are rarely included at the lower tiers.
